Workbook

Sheet Dashboard
B1: CoW Swap — QA Test Checklist
B2: swap.cow.fi | Version 1.0 | May 2026
B4: TEST EXECUTION SUMMARY
B5: Category | C5: Total | D5: Pass | E5: Fail | F5: Blocked | G5: % Pass
B6: Wallet Connection | C6: =COUNTA(WalletConnection!H5:H200) -> 17 | D6: =COUNTIF(WalletConnection!H5:H200,"Pass") -> 0 | E6: =COUNTIF(WalletConnection!H5:H200,"Fail") -> 0 | F6: =COUNTIF(WalletConnection!H5:H200,"Blocked") -> 0 | G6: =IF(C6=0,"-",D6/C6) -> 0
B7: Safe Wallet | C7: =COUNTA(SafeWallet!H5:H200) -> 16 | D7: =COUNTIF(SafeWallet!H5:H200,"Pass") -> 0 | E7: =COUNTIF(SafeWallet!H5:H200,"Fail") -> 0 | F7: =COUNTIF(SafeWallet!H5:H200,"Blocked") -> 0 | G7: =IF(C7=0,"-",D7/C7) -> 0
B8: Smart Accounts | C8: =COUNTA(SmartAccounts!H5:H200) -> 12 | D8: =COUNTIF(SmartAccounts!H5:H200,"Pass") -> 0 | E8: =COUNTIF(SmartAccounts!H5:H200,"Fail") -> 0 | F8: =COUNTIF(SmartAccounts!H5:H200,"Blocked") -> 0 | G8: =IF(C8=0,"-",D8/C8) -> 0
B9: Market Orders (Swap) | C9: =COUNTA(MarketOrders!H5:H200) -> 79 | D9: =COUNTIF(MarketOrders!H5:H200,"Pass") -> 0 | E9: =COUNTIF(MarketOrders!H5:H200,"Fail") -> 0 | F9: =COUNTIF(MarketOrders!H5:H200,"Blocked") -> 0 | G9: =IF(C9=0,"-",D9/C9) -> 0
B10: Limit Orders | C10: =COUNTA(LimitOrders!H5:H200) -> 66 | D10: =COUNTIF(LimitOrders!H5:H199,"Pass") -> 0 | E10: =COUNTIF(LimitOrders!H5:H199,"Fail") -> 0 | F10: =COUNTIF(LimitOrders!H5:H199,"Blocked") -> 0 | G10: =IF(C10=0,"-",D10/C10) -> 0
B11: TWAP Orders | C11: =COUNTA(TWAPOrders!H5:H201) -> 57 | D11: =COUNTIF(TWAPOrders!H5:H195,"Pass") -> 0 | E11: =COUNTIF(TWAPOrders!H5:H195,"Fail") -> 0 | F11: =COUNTIF(TWAPOrders!H5:H195,"Blocked") -> 0 | G11: =IF(C11=0,"-",D11/C11) -> 0
B12: Cross-Chain Swaps | C12: =COUNTA(CrossChain!H5:H195) -> 31 | D12: =COUNTIF(CrossChain!H5:H195,"Pass") -> 0 | E12: =COUNTIF(CrossChain!H5:H195,"Fail") -> 0 | F12: =COUNTIF(CrossChain!H5:H195,"Blocked") -> 0 | G12: =IF(C12=0,"-",D12/C12) -> 0
B13: UI / UX | C13: =COUNTA(UIUX!H5:H200) -> 23 | D13: =COUNTIF(UIUX!H5:H200,"Pass") -> 0 | E13: =COUNTIF(UIUX!H5:H200,"Fail") -> 0 | F13: =COUNTIF(UIUX!H5:H200,"Blocked") -> 0 | G13: =IF(C13=0,"-",D13/C13) -> 0
B14: Hooks | C14: =COUNTA(Hooks!H5:H200) -> 7 | D14: =COUNTIF(Hooks!H5:H200,"Pass") -> 0 | E14: =COUNTIF(Hooks!H5:H200,"Fail") -> 0 | F14: =COUNTIF(Hooks!H5:H200,"Blocked") -> 0 | G14: =IF(C14=0,"-",D14/C14) -> 0
B15: Account Pages | C15: =COUNTA(AccountOverview!H5:H212) -> 35 | D15: =COUNTIF(AccountOverview!H5:H212,"Pass") -> 0 | E15: =COUNTIF(AccountOverview!H5:H212,"Fail") -> 0 | F15: =COUNTIF(AccountOverview!H5:H212,"Blocked") -> 0 | G15: =IF(C15=0,"-",D15/C15) -> 0
B16: RWA (Ondo & xStocks) | C16: =COUNTA(RWA!H5:H200) -> 19 | D16: =COUNTIF(RWA!H5:H200,"Pass") -> 0 | E16: =COUNTIF(RWA!H5:H200,"Fail") -> 0 | F16: =COUNTIF(RWA!H5:H200,"Blocked") -> 0 | G16: =IFERROR(D16/C16,0) -> 0
B17: TOTAL | C17: =SUM(C6:C16) -> 362 | D17: =SUM(D6:D16) -> 0 | E17: =SUM(E6:E16) -> 0 | F17: =SUM(F6:F16) -> 0 | G17: =IF(C17=0,"-",D17/C17) -> 0
B19: STATUS LEGEND
B20: ✅ Pass
B21: ❌ Fail
B22: ⏸ Blocked
B23: ⬜ Not Run

Sheet WalletConnection
A1: Wallet Connection Tests
A2: CoW Swap | swap.cow.fi | WalletConnection
A4: ID | B4: Test Name | C4: Priority | D4: Type | E4: Preconditions | F4: Test Steps | G4: Expected Result | H4: Status | I4: Notes / Defect ID
A5: WC-01 | B5: Connect MetaMask wallet | C5: High | D5: Functional | E5: MetaMask installed & unlocked | F5: 1. Open swap.cow.fi 2. Click 'Connect Wallet' 3. Select MetaMask 4. Approve connection in MetaMask popup | G5: 1. Wallet address shown in header 2. correct network displayed | H5: Not Run
A6: WC-02 | B6: Connect WalletConnect | C6: High | D6: Functional | E6: Mobile wallet with WalletConnect | F6: 1. Click 'Connect Wallet' 2. Select WalletConnect 3. Scan QR with mobile wallet | G6: 1. Wallet connected 2. address shown correctly | H6: Not Run
A7: WC-03 | B7: Connect Rabby wallet | C7: Medium | D7: Functional | E7: Rabby extension installed | F7: 1. Click 'Connect Wallet' 2. Select Rabby 3. Approve | G7: Wallet connected successfully | H7: Not Run
A8: WC-04 | B8: Connect hardware wallet via MetaMask | C8: Medium | D8: Functional | E8: Trezor / Ledger linked to MetaMask | F8: 1. Connect MetaMask (hardware) 2. Select hardware account | G8: 1. Hardware wallet address shown 2. EIP-712 signing prompt works | H8: Not Run
A9: WC-05 | B9: Switch network while connected | C9: High | D9: Functional | E9: Wallet connected on Ethereum Mainnet | F9: 1. Switch to Gnosis Chain in wallet 2. Observe UI update | G9: 1. UI reflects new network 2. token list updates accordingly | H9: Not Run
A10: WC-06 | B10: Disconnect wallet | C10: Medium | D10: Functional | E10: Wallet currently connected | F10: 1. Click wallet address 2. Select 'Disconnect' | G10: 1. Wallet disconnected 2. connect button restored | H10: Not Run
A11: WC-07 | B11: Session persistence on page reload | C11: Low | D11: Functional | E11: Wallet connected | F11: 1. Reload the page | G11: 1. Wallet remains connected 2. no re-auth required | H11: Not Run
A12: WC-08 | B12: Connect via mobile app (in-app browser) | C12: High | D12: Functional | E12: Mobile wallet app installed (e.g. MetaMask Mobile, Trust Wallet); mobile device | F12: 1. Open wallet app on mobile device 2. Navigate to the in-app browser (DApp browser) 3. Enter https://swap.cow.fi 4. Tap 'Connect Wallet' 5. Select the injected wallet option (should auto-detect mobile wallet) 6. Approve connection in wallet prompt | G12: 1. Wallet auto-detected as injected provider 2. address shown in header 3. correct chain displayed 4. swap UI fully functional in mobile in-app browser | H12: Not Run
A13: WC-09 | B13: Connect via mobile app — WalletConnect fallback | C13: Medium | D13: Functional | E13: Mobile device with wallet that supports WalletConnect v2 but does NOT inject a provider (e.g. opened in system browser, not in-app browser) | F13: 1. Open swap.cow.fi in mobile system browser (Safari / Chrome) 2. Tap 'Connect Wallet' 3. Select WalletConnect 4. Tap the deep-link / 'Open in wallet' button 5. Approve connection in the wallet app | G13: 1. WalletConnect session established via deep-link 2. wallet address shown 3. no duplicate connection prompts 4. session stable across mobile browser background/foreground cycles | H13: Not Run
A14: WC-10 | B14: Connect inside wallet's built-in browser (injected provider detection) | C14: High | D14: Functional | E14: Wallet with built-in DApp browser (MetaMask Mobile, Coinbase Wallet, Rabby Mobile); navigate to swap.cow.fi from within that browser | F14: 1. Open wallet app 2. Go to the built-in browser / DApp browser tab 3. Navigate to swap.cow.fi 4. Observe whether wallet is auto-detected 5. If not auto-detected, tap 'Connect Wallet' and confirm injected option is listed 6. Approve connection | G14: 1. window.ethereum injected correctly 2. wallet listed as first option 3. no WalletConnect QR shown unnecessarily 4. connection completes without leaving the browser view | H14: Not Run
A15: WC-11 | B15: Connect Safe via WalletConnect (external signer) | C15: High | D15: Functional | E15: Safe wallet deployed on target network; at least one signer device (desktop or mobile wallet with WC v2 support); Safe does NOT need to be used as Safe App | F15: 1. Open swap.cow.fi in a regular browser 2. Click 'Connect Wallet' 3. Select WalletConnect 4. Copy or scan the WC URI 5. In the Safe interface (app.safe.global), go to WalletConnect section and paste the URI 6. Approve the connection from Safe 7. Collect required signer approvals if threshold > 1 | G15: 1. Safe address (0x…) shown as connected wallet 2. UI recognises smart contract wallet 3. ERC-1271 signing used for order placement 4. TWAP / advanced order types accessible | H15: Not Run
A16: WC-12 | B16: Open CoW Swap inside Safe App (native Safe App integration) | C16: High | D16: Functional | E16: Safe wallet exists; access to app.safe.global or Safe mobile app | F16: 1. Log in to app.safe.global with Safe owner wallet 2. Navigate to Apps → Search for 'CoW Swap' 3. Open CoW Swap Safe App 4. Verify auto-connection (no manual connect step should be required) 5. Attempt a swap or limit order to confirm full functionality | G16: 1. CoW Swap loads inside Safe iframe 2. Safe address auto-connected 3. no extra connect step 4. TWAP tab visible and accessible 5. order signing routes through Safe transaction queue | H16: Not Run | I16: Also test in Safe mobile app if available
A17: WC-13 | B17: Multiple tabs — connection state isolation | C17: High | D17: Functional | E17: Desktop browser; wallet extension installed (e.g. MetaMask) | F17: 1. Open swap.cow.fi in Tab A; connect Wallet A 2. Open swap.cow.fi in Tab B (same browser, new tab) 3. In Tab B, connect a different account (switch account in MetaMask) 4. Switch back to Tab A and interact (e.g. refresh quote) 5. Repeat with one tab connected and one tab with no wallet | G17: 1. Each tab reflects its own connection state without corrupting the other 2. Tab A does not silently adopt Tab B's account change 3. wallet account changes propagate correctly only to the active/focused tab OR consistently to all tabs per wallet extension behaviour | H17: Not Run | I17: Document actual wallet extension behaviour (MetaMask broadcasts accountsChanged to all tabs — this is expected and should be noted, not flagged as a bug)
A18: WC-14 | B18: Multiple tabs — no duplicate connection prompts | C18: Medium | D18: Functional | E18: swap.cow.fi open in 2+ tabs simultaneously | F18: 1. Open swap.cow.fi in Tab A and Tab B 2. In Tab A, click 'Connect Wallet' and begin connection flow 3. Switch to Tab B without completing connection in Tab A 4. Observe Tab B's state 5. Complete connection in Tab A; verify Tab B updates appropriately | G18: 1. Tab B does not launch its own unsolicited connection prompt 2. completing connection in Tab A does not leave Tab B in a broken/mixed state 3. no JS errors in console related to provider conflicts | H18: Not Run
A19: WC-15 | B19: Account modal: connected wallet address displayed correctly | C19: High | D19: Functional | E19: Wallet connected | F19: 1. Open account modal 2. Verify wallet address shown 3. Compare to wallet extension address | G19: 1. Full or truncated wallet address shown and matches connected wallet 2. ENS name shown if resolved 3. correct for all wallet types (EOA, Safe, MM Smart Account, Base SA) | H19: Not Run
A20: WC-16 | B20: Account modal: history shows last 10 orders | C20: Medium | D20: Functional | E20: Wallet connected | F20: 1. Open account modal | G20: 1. Up to last 10 orders shown 2. link to CoW Explorer provided for full history 3. orders show status (In Progress, Filled, Cancelled, Expired) 4. each order links to explorer detail page | H20: Not Run
A21: WC-17 | B21: Account modal: network switch updates displayed data | C21: Medium | D21: Functional | E21: Wallet connected on Ethereum Mainnet | F21: 1. View account overview on Mainnet 2. Switch wallet to Gnosis Chain 3. Observe account data refresh | G21: 1. Account data updates to reflect new chain 2. token balances, order history, and proxy info shown for the newly connected chain 3. no stale Mainnet data persists | H21: Not Run

Sheet SafeWallet
A1: Safe Wallet Tests
A2: CoW Swap | swap.cow.fi | SafeWallet
A4: ID | B4: Test Name | C4: Priority | D4: Type | E4: Preconditions | F4: Test Steps | G4: Expected Result | H4: Status | I4: Notes / Defect ID
A5: SW-01 | B5: Safe App: CoW Swap opens inside Safe — auto-connection | C5: High | D5: Functional | E5: Safe wallet exists on a supported chain; access to app.safe.global or Safe mobile app | F5: 1. Log in to app.safe.global with a Safe owner wallet 2. Navigate to Apps → search 'CoW Swap' 3. Open CoW Swap Safe App 4. Observe connection state — no manual connect step expected | G5: 1. CoW Swap loads inside Safe iframe 2. Safe address auto-connected 3. no 'Connect Wallet' prompt 4. Safe App License Fee (0.1%) shown in fee fields fior non-correlated assets | H5: Not Run | I5: This is the primary Safe integration path. Safe charges its own 0.1% fee when app is opened here correlated assets listed in https://cms.cow.fi/admin/content-manager/collection-types/api::correlated-token.correlated-token?page=1&pageSize=10&sort=name:ASC
A6: SW-02 | B6: Safe App: order signing routes through Safe tx queue | C6: High | D6: Functional | E6: CoW Swap open inside Safe App; Safe threshold ≥ 1 | F6: 1. Place a market swap order inside CoW Swap Safe App 2. Observe signing flow — should NOT open individual EOA wallet prompt 3. Verify new transaction appears in Safe transaction queue 4. Collect required signer signatures 5. Execute the transaction | G6: 1. Safe TX created in queue 2. order only submitted to CoW Protocol API after on-chain Safe TX executes 3. no off-chain EOA signature bypass 4. threshold satisfied before execution | H6: Not Run
A7: SW-03 | B7: Safe via WalletConnect — desktop Safe app (app.safe.global) | C7: High | D7: Functional | E7: Safe wallet deployed; access to app.safe.global; no Safe App used — connecting externally via WC | F7: 1. Open swap.cow.fi in a separate browser tab 2. Click 'Connect Wallet' → select WalletConnect 3. Copy the WC URI 4. In app.safe.global → WalletConnect section → paste URI 5. Approve connection from Safe desktop app 6. Return to swap.cow.fi | G7: 1. Safe address shown as connected wallet in CoW Swap 2. UI recognises SC wallet (ERC-1271 signing) 3. TWAP available if fallback handler installed 4. Safe App License Fee NOT applied (only applies inside Safe App iframe) 5. no gasless transactions (SC wallet) | H7: Not Run | I7: Key difference from SW-01: no Safe App fee; no gasless; orders still sign via Safe tx queue
A8: SW-04 | B8: Safe via WalletConnect — mobile Safe app | C8: High | D8: Functional | E8: Safe wallet; Safe mobile app installed; swap.cow.fi open in desktop browser | F8: 1. Open swap.cow.fi on desktop 2. Click 'Connect Wallet' → WalletConnect 3. Scan WC QR code with Safe mobile app 4. Approve connection in Safe mobile 5. Place a swap order on desktop 6. Approve the Safe TX in Safe mobile app (collect signatures) | G8: 1. Safe address connected 2. order placement triggers Safe TX in mobile app queue 3. all signers must approve via mobile 4. Safe App fee NOT applied 5. no gasless 6. signing is on-chain | H8: Not Run | I8: This type of connection does not support transactions bundling
A9: SW-05 | B9: Safe imported in Rabby wallet — connection and signing | C9: High | D9: Functional | E9: Rabby wallet extension installed; Safe wallet imported into Rabby (Rabby supports Safe as an account type) | F9: 1. In Rabby, switch to the imported Safe account 2. Open swap.cow.fi 3. Connect wallet — Rabby injected provider selected 4. Place a swap order 5. Observe signing flow in Rabby | G9: 1. Safe address shown as connected 2. Rabby handles signing on behalf of Safe 3. order may use off-chain ERC-1271 signature (Rabby can simulate Safe signing) or route through Safe TX — verify which path Rabby uses 4. TWAP availability depends on fallback handler | H9: Not Run | I9: Rabby's Safe import allows off-chain-style signing for Safe — behaviour may differ from native Safe App or WC connection. Verify fee logic: no Safe App fee; check whether gasless/bundling applies. Also, not TX bundling. Onchain TX resoinses are not detected: see https://github.com/cowprotocol/cowswap/issues/6755
A10: SW-06 | B10: Fee: Safe App License Fee (0.1%) applied inside Safe App | C10: High | D10: Functional | E10: CoW Swap open inside Safe App (SW-01 or SW-06 context) | F10: 1. Open CoW Swap inside Safe App (app.safe.global or mobile) 2. Select any non-correlated token pair 3. Enter a swap amount 4. Observe fee fields on the swap form and confirm modal | G10: 1. 'Safe App License Fee (0.1%)' label appears on swap form 2. shows estimated fee in tokens and USD 3. same label on Confirm modal 4. Receive (incl. costs) tooltip includes Safe App fee 5. fee NOT shown for correlated token pairs (e.g. USDC/DAI) | H10: Not Run | I10: Per spec: Safe charges 0.1% fee inside Safe App. Correlated pairs exempt correlated assets listed in https://cms.cow.fi/admin/content-manager/collection-types/api::correlated-token.correlated-token?page=1&pageSize=10&sort=name:ASC
A11: SW-07 | B11: Fee: Safe App License Fee NOT applied via WalletConnect | C11: High | D11: Functional | E11: Safe connected via WalletConnect (SW-03 or SW-04), NOT inside Safe App iframe | F11: 1. Connect Safe via WC to swap.cow.fi 2. Select same token pair as SW-07 3. Enter same amount 4. Compare fee fields | G11: 1. No 'Safe App License Fee' shown 2. only standard CoW Protocol network costs and any applicable volume fee 3. fee section shows standard breakdown | H11: Not Run | I11: Safe App fee = iframe context only, not WC context
A12: SW-08 | B12: Fee: SC wallet — no gasless transactions, '+gas' shown in Network costs | C12: High | D12: Functional | E12: Any Safe connection mode (SW-01 through SW-06) | F12: 1. Connect via any Safe method 2. Load a swap quote 3. Observe Network costs (est.) field 4. Check Receive (incl. costs) / From (incl. costs) tooltips | G12: 1. Network costs field shows '+gas' suffix 2. Fee field absent from Receive/From tooltips (when no other fee types present) 3. transactions are NOT gasless — SC wallets execute on-chain TXs | H12: Not Run | I12: Per spec: 'Transactions in SC wallets are not gasless ones. Fee field is absent from tooltips when no other fee types. Network costs shows +gas'
A13: SW-09 | B13: Fee: Safe App fee exempt for correlated token pairs | C13: Medium | D13: Functional | E13: CoW Swap inside Safe App; correlated token pair selected (e.g. USDC/DAI, USDC/USDT) | F13: 1. Open CoW Swap inside Safe App 2. Select a correlated token pair (stablecoin↔stablecoin) 3. Observe fee fields | G13: 1. Safe App License Fee NOT shown for correlated pairs 2. fee section shows 'Free' or standard network costs only | H13: Not Run | I13: Per spec: 'Fees not set to correlated token pairs' correlated assets listed in https://cms.cow.fi/admin/content-manager/collection-types/api::correlated-token.correlated-token?page=1&pageSize=10&sort=name:ASC
A14: SW-10 | B14: Bundling: Safe App — 'Approve + Swap' in single Safe TX | C14: High | D14: Functional | E14: CoW Swap inside Safe App; ERC-20 token with no prior approval | F14: 1. Select unapproved ERC-20 sell token inside Safe App 2. Observe action button area 3. Verify 'Token bundling' banner shown 4. Click 'Approve + Swap' 5. Check Safe TX queue | G14: 1. Both approval and swap bundled into single Safe TX 2. 'Approve + Swap' button shown 3. one TX in Safe queue (not two separate) 4. both signers approve once | H14: Not Run | I14: Safe App context supports bundling. Contrast with SW-13 for WC context
A15: SW-11 | B15: Bundling: WC-connected Safe — separate approval TX required | C15: High | D15: Functional | E15: Safe connected via WalletConnect; ERC-20 token with no prior approval | F15: 1. Connect Safe via WC 2. Select unapproved ERC-20 sell token 3. Observe action button — check if bundling banner appears 4. Complete approval flow | G15: 1. Both approval and swap bundled into single Safe TX 2. 'Approve + Swap' button shown 3. one TX in Safe queue (not two separate) 4. both signers approve once | H15: Not Run
A16: SW-12 | B16: Bundling: Rabby + Safe — verify whether bundling is supported | C16: Medium | D16: Functional | E16: Safe imported in Rabby; unapproved ERC-20 sell token | F16: 1. Connect via Rabby with imported Safe account 2. Select unapproved token 3. Observe action button and bundling banner presence | G16: 1. Bundling NOT available via WC connection 2. 'Allow CoW Swap to use your token' button shown (not Approve+Swap) 3. separate approval TX required before swap can proceed | H16: Not Run
A17: SW-13 | B17: TX deadline: Safe SC wallet max deadline = 720 min | C17: Medium | D17: Functional | E17: Safe wallet connected (any method); Settings open | F17: 1. Connect Safe wallet 2. Open Settings → TX deadline 3. Check maximum allowed deadline 4. Compare to EOA max (180 min) | G17: 1. Max deadline = 720 min for SC wallets vs 180 min for EOA 2. value above 720 rejected or clamped 3. default = 30 min unchanged | H17: Not Run
A18: SW-14 | B18: ETH-flow: bundling | C18: High | D18: Functional | E18: The app is opened inside Safe or connected to app using WC | F18: 1. Select ETH as sell token with Safe 2. Press on the "Wrap ETH and Swap button' | G18: Both wrapping, approval (if needed) and swap bundled into single Safe TX | H18: Not Run
A19: SW-15 | B19: ETH-flow: Safe uses wrap-WETH instead of native ETH-flow | C19: High | D19: Functional | E19: Safe wallet connected (any method); ETH in Safe | F19: 1. Select ETH as sell token with Safe connected via Rabby or connected to iOS safe app 2. Observe flow shown — should be wrap-WETH, not ETH-flow 3. Wrap ETH → WETH via Safe TX 4. Swap WETH as normal ERC-20 | G19: 1. ETH-flow NOT used for SC wallets 2. 'Wrap your ETH' section shown 3. wrapping creates Safe TX in queue 4. after WETH received, swap proceeds as ERC-20 order | H19: Not Run
A20: SW-16 | B20: TWAP: requires Safe with ExtensibleFallbackHandler not installed | C20: High | D20: Functional | E20: The app is opened inside Safe or connected to app using WC | F20: 1. Connect Safe without fallback handler | G20: Warning on the form is displayed to set up the FB handler A user needs to check the box before proceeding with an order Setting up the handler is included into the bundle along with TWAP order placement TX | H20: Not Run

Sheet SmartAccounts
A1: Smart Account Tests
A2: CoW Swap | swap.cow.fi | SmartAccounts
A4: ID | B4: Test Name | C4: Priority | D4: Type | E4: Preconditions | F4: Test Steps | G4: Expected Result | H4: Status | I4: Notes / Defect ID
A5: SA-01 | B5: MetaMask Smart Account: detected as EOA wallet in CoW Swap | C5: High | D5: Functional | E5: MetaMask extension with Smart Account (ERC-4337 based) enabled; account selected in MetaMask | F5: 1. Open MetaMask and switch to Smart Account 2. Connect to swap.cow.fi 3. Observe how CoW Swap classifies the wallet type | G5: 1. CoW Swap treats MetaMask Smart Account as a regular EOA wallet 2. no SC wallet UI shown 3. standard EOA swap flow available 4. ETH-flow (native ETH orders) accessible | H5: Not Run | I5: MM Smart Accounts are handled as regular EOA wallets — they appear as injected provider with EOA-like interface
A6: SA-02 | B6: MetaMask Smart Account: off-chain order signing works (EIP-712) | C6: High | D6: Functional | E6: MetaMask Smart Account connected | F6: 1. Connect MetaMask Smart Account 2. Place a market swap order 3. Observe signing prompt in MetaMask | G6: 1. EIP-712 typed data signing prompt shown (same as regular EOA) 2. no Safe-style TX queue 3. order submitted as off-chain intent 4. signs like EOA | H6: Not Run
A7: SA-03 | B7: MetaMask Smart Account: gasless permit available — same as EOA | C7: High | D7: Functional | E7: MetaMask Smart Account; permit-compatible ERC-20 sell token | F7: 1. Connect MetaMask Smart Account 2. Select permit-compatible sell token (e.g. USDC) 3. Observe approval flow — gasless permit option should be offered 4. Sign the permit message 5. Verify no on-chain approval TX is submitted | G7: 1. Gasless permit (EIP-2612) offered, same as regular EOA 2. off-chain permit signature works 3. no on-chain approval TX needed 4. same partial permit side-effect risk applies | H7: Not Run | I7: MM Smart Account treated as EOA for permit purposes. Warning about partial permit breaking other orders should appear in the same way as for EOA.
A8: SA-04 | B8: MetaMask Smart Account: ETH-flow accessible | C8: High | D8: Functional | E8: MetaMask Smart Account connected; ETH balance > 0 | F8: 1. Select ETH as sell token with MetaMask Smart Account 2. Observe flow — should be ETH-flow, not wrap-WETH | G8: 1. Native ETH-flow available (not wrap-WETH fallback) 2. UI does not show 'Wrap your ETH' section for SC wallet 3. order submitted on-chain as ETH-flow | H8: Not Run | I8: EOA treatment means ETH-flow is available, unlike Safe/Base SC wallets which must wrap first
A9: SA-05 | B9: MetaMask Smart Account: TWAP tab shows 'create Safe' prompt | C9: Medium | D9: Functional | E9: MetaMask Smart Account connected | F9: 1. Navigate to TWAP tab with MetaMask Smart Account | G9: TWAP form shows 'Unsupproted wallet' | H9: Not Run | I9: MM Smart Accounts do not satisfy TWAP's Safe requirement
A10: SA-06 | B10: MetaMask Smart Account: TX deadline max = 180 min (EOA limit) | C10: Medium | D10: Functional | E10: MetaMask Smart Account connected; Settings open | F10: 1. Open Settings → TX deadline 2. Check max value | G10: 1. Max TX deadline = 180 min (EOA limit, not 720 min SC limit) 2. consistent with EOA treatment | H10: Not Run
A11: SA-07 | B11: Base Smart Account: detected as SC wallet in CoW Swap | C11: High | D11: Functional | E11: Coinbase Wallet with Base Smart Account (ERC-4337) enabled; connected to swap.cow.fi | F11: 1. Connect Coinbase Wallet with Base Smart Account active 2. Observe how CoW Swap classifies the wallet | G11: 1. CoW Swap detects Base Smart Account as SC wallet 2. SC wallet UI behaviors applied: no ETH-flow, wrap-WETH required, no gasless permit, TX deadline max = 720 min, '+gas' in Network costs | H11: Not Run | I11: Base Smart Accounts act as SC wallets — same class as Safe but different provider
A12: SA-08 | B12: Base Smart Account: ETH requires wrap-WETH flow | C12: High | D12: Functional | E12: Base Smart Account connected; ETH balance > 0 | F12: 1. Select ETH as sell token 2. Observe UI | G12: 1. 'Wrap your ETH' section shown 2. native ETH-flow NOT available 3. must wrap ETH → WETH before swapping 4. same as Safe SC wallet ETH handling | H12: Not Run
A13: SA-09 | B13: Base Smart Account: gasless permit NOT available | C13: High | D13: Functional | E13: Base Smart Account connected; permit-compatible ERC-20 selected | F13: 1. Select a permit-compatible token (e.g. USDC) 2. Observe approval UI | G13: 1. No gasless permit option offered 2. standard on-chain approval TX required 3. no EIP-2612 permit signing prompt | H13: Not Run | I13: SC wallets cannot sign EIP-712 permits — applies to Base Smart Accounts too
A14: SA-10 | B14: Base Smart Account: bundling (Approve+Swap) supported | C14: High | D14: Functional | E14: Base Smart Account; unapproved ERC-20 sell token | F14: 1. Connect Base Smart Account 2. Select unapproved ERC-20 3. Observe action button | G14: User needs to approve a token first, then place an order | H14: Not Run
A15: SA-11 | B15: Base Smart Account: TX deadline max = 720 min (SC wallet limit) | C15: Medium | D15: Functional | E15: Base Smart Account connected; Settings open | F15: 1. Open Settings → TX deadline 2. Check max value | G15: 1. Max TX deadline = 720 min (SC wallet limit) 2. not limited to 180 min EOA limit | H15: Not Run
A16: SA-12 | B16: Base Smart Account: TWAP availability | C16: Medium | D16: Functional | E16: Base Smart Account connected | F16: 1. Navigate to TWAP tab 2. Check whether TWAP is available or what prompt is shown | G16: TWAP form shows 'Unsupproted wallet' | H16: Not Run | I16: Expected: TWAP not available for Base SA (Safe-specific feature); document actual prompt shown

Sheet MarketOrders
A1: Market Orders (Swap) Tests
A2: CoW Swap | swap.cow.fi | MarketOrders
A4: ID | B4: Test Name | C4: Priority | D4: Type | E4: Preconditions | F4: Test Steps | G4: Expected Result | H4: Status | I4: Notes / Defect ID
A5: MO-01 | B5: Sell order: ERC-20 → ETH | C5: High | D5: Functional | E5: EOA wallet connected; USDC balance > 0 | F5: 1. Select USDC as sell token, ETH as buy token 2. Enter sell amount 3. Approve if needed 4. Click Swap and sign | G5: 1. Order submitted off-chain 2. appears in open orders with status Open | H5: Not Run
A6: MO-02 | B6: Sell order: ERC-20 → ERC-20 | C6: High | D6: Functional | E6: EOA wallet; USDC balance > 0 | F6: 1. Select USDC → WETH 2. Enter amount 3. Approve token if needed 4. Swap and sign | G6: 1. Order submitted off-chain 2. appears in open orders with status Open | H6: Not Run
A7: MO-03 | B7: Buy order: specify exact buy amount (ERC-20) | C7: High | D7: Functional | E7: EOA wallet; sufficient sell token balance; buy order type selected in UI | F7: 2. Select USDC as sell token, WETH as buy token 3. Enter exact buy amount (e.g. 0.5 WETH) 4. Observe 'From (incl. costs)' sell amount calculated 5. Check Maximum sent amount (Receive incl. costs + Slippage) 6. Place order | G7: 1. Order submitted off-chain 2. appears in open orders with status Open | H7: Not Run
A8: MO-04 | B8: Buy order: approval amount includes slippage buffer | C8: High | D8: Functional | E8: token not yet approved | F8: 1. Specify a buy order for token X 2. Observe the approval prompt amount 3. Compare approval amount to 'From (incl. costs)' + slippage % | G8: Approval amount = Maximum sent amount = Receive (incl. costs) + slippage buffer+1% | H8: Not Run
A9: MO-05 | B9: Buy order: ETH as sell token (ETH-flow buy not supported) | C9: Medium | D9: Functional | E9: ETH-flow context (ETH as sell token, EOA wallet) | F9: 1. Select ETH as sell token 2. Attempt to switch to Buy order mode | G9: 1. Buy field is disabled for ETH-flow 2. only Sell order type available | H9: Not Run | I9: ETH-flow is sell-only per spec
A10: MO-06 | B10: Swap form: To field amount calculation | C10: High | D10: Functional | E10: Both tokens selected; sell amount entered | F10: 1. Enter sell amount (e.g. 100 USDC) 2. Observe To field 3. Verify: To amount = Sell amount × Price (from BE) 4. Verify USD estimation shown for both fields 5. Verify price impact shown near USD estimation with tooltip 'Price impact due to current liquidity levels' | G10: 1. To amount = Sell amount × Price (e.g. if price of 1 ETH = 16 GNO, selling 1 ETH shows 16 GNO) 2. USD estimations present 3. price impact % shown | H10: Not Run | I10: Per spec: 'Amount in the To field = Sell amount × Price'
A11: MO-07 | B11: Swap form: 'Receive (incl. costs)' field calculation | C11: High | D11: Functional | E11: Quote loaded with non-zero fee and network costs | F11: 1. Load a swap quote 2. Hover over 'Receive (incl. costs)' tooltip 3. Verify tooltip grid shows: Before costs, Network costs, Fee, TO value 4. Verify: Receive (incl. costs) = To amount − Network costs − Fee | G11: 1. Tooltip shows calculation breakdown 2. TO = Before costs − Network costs 3. Receive (incl. costs) matches formula 4. values consistent with Network costs (est.) field | H11: Not Run | I11: Per spec: 'Calculated as Receive amount − Network costs − fee'
A12: MO-08 | B12: Swap form: 'Minimum receive' calculation in Confirm modal | C12: High | D12: Functional | E12: Swap confirm modal open | F12: 1. Proceed to Confirm Swap modal 2. Note 'Expected to receive' value 3. Note slippage % in settings 4. Verify 'Minimum receive' = Expected to receive × (1 − slippage% / 100) | G12: 1. Minimum receive = Expected to receive × (1 − slippage/100) 2. field shown read-only 3. value updates when slippage changes | H12: Not Run | I12: Per spec: 'Minimum receive = Expected to receive × (1 − slippage%/100)'
A13: MO-09 | B13: Swap form: MAX button deducts 0.01 ETH for gas | C13: Medium | D13: Functional | E13: ETH selected as sell token; ETH balance > 0.01, user is connected to EOA wallet | F13: 1. Select ETH as sell token 2. Click MAX button 3. Observe the filled amount | G13: 1. Amount = ETH balance − 0.01 (to cover gas costs) 2. not the full balance | H13: Not Run | I13: This does not apply to smart-contract wallets: max button preseletcs 100% of a native token
A14: MO-10 | B14: Confirm modal: price update banner | C14: Medium | D14: Functional | E14: Confirm Swap modal open; quote refreshes while modal is open | F14: 1. Open Confirm Swap modal 2. Wait for price to update 3. Observe banner 4. Click Accept on the banner | G14: 1. 'Price updated' banner appears 2. Confirm Swap button disabled until Accept clicked 3. new price reflected after accepting | H14: Not Run
A15: MO-11 | B15: ETH-flow: place ETH sell order (EOA wallet) | C15: High | D15: Functional | E15: EOA wallet connected; ETH balance > 0; | F15: 1. Select ETH as sell token, any ERC-20 as buy token 2. Enter ETH amount 3. Review form: From field (ETH amount + USD), To field (buy amount + USD + price impact), Receive (incl. costs), Price, Fee, Network costs, Slippage, Expiration 4. Click Swap 5. Sign the ON-CHAIN transaction in wallet | G15: 1. ETH-flow order submitted on-chain (not off-chain intent) 2. status shows 'Creating' with TX creation hash 3. progresses to 'Open' once TX executes 4. ETH deducted from balance at Open state | H15: Not Run | I15: ETH-flow uses on-chain TX, not off-chain signature. SC wallets use classic wrap-WETH flow instead
A16: MO-12 | B16: ETH-flow: SC wallet falls back to wrap-WETH flow | C16: High | D16: Functional | E16: Smart contract wallet (Safe via Rabby or Base smart wallet) connected; ETH balance > 0 | F16: 1. Select ETH as sell token 2. Observe UI — 'Wrap your ETH' section should appear 3. Wrap ETH → WETH 4. Proceed with WETH swap as normal ERC-20 | G16: 1. SC wallet does not use ETH-flow 2. classic wrap-then-swap flow shown 3. no direct on-chain ETH order created | H16: Not Run
A17: MO-13 | B17: ETH-flow: SC wallet: Safe+bundling | C17: High | D17: Functional | E17: Safe viz WC or the app inside Safe connected; ETH balance > 0 | F17: 1. Select ETH as sell token, an amount to sell 2. Pick ERC 20 token to buy 3. verify the button | G17: 1. SC wallet does not use ETH-flow 2. classic: it bundles wrap+approveWETH(if needed) and a swap in 1 transaction. | H17: Not Run
A18: MO-14 | B18: ETH-flow: order status lifecycle | C18: High | D18: Functional | E18: ETH-flow order placed | F18: 1. Submit ETH-flow order → verify status = 'Creating'; TX hash shown 2. Wait for TX to execute → verify status = 'Open'; ETH deducted; Explorer link appears 3. Wait for fill → verify status = 'Filled'; buy token in wallet; 3rd stepper circle green; cancel no longer possible | G18: 1. Status transitions: Creating → Open → Filled 2. correct TX links at each step 3. ETH deducted at Open 4. buy token received at Filled | H18: Not Run
A19: MO-15 | B19: ETH-flow: order submission TX fails | C19: Medium | D19: Negative | E19: ETH-flow order submitted; TX fails on-chain | F19: 1. Submit ETH-flow order 2. Simulate or observe a TX failure (e.g. gas too low) 3. Check order status and balance | G19: 1. Status = 'Failed' 2. ETH NOT deducted (only TX costs) 3. stepper shown in red 4. cancel not possible 5. TX hash still linked | H19: Not Run
A20: MO-16 | B20: ETH-flow: cancel order (on-chain cancellation) | C20: Medium | D20: Functional | E20: ETH-flow order in 'Open' or 'Creating' state | F20: 1. Click cancel on open ETH-flow order 2. Confirm cancellation TX in wallet 3. Monitor status → 'Cancelling' 4. Wait for cancellation TX to mine → status 'Cancelled' | G20: 1. 'Cancelling' state: ETH still deducted, cancellation TX link shown under 3rd stepper step 2. 'Cancelled' state: ETH NOT returned (only TX costs taken) 3. 2nd step shown in red | H20: Not Run | I20: ETH cancellation is on-chain. Cancelled ETH is NOT refunded — only TX gas costs
A21: MO-17 | B21: ETH-flow: order expired — ETH refunded | C21: Medium | D21: Functional | E21: ETH-flow order in Open state; TX deadline reached without fill | F21: 1. Place ETH-flow order with short deadline 2. Let it expire without fill 3. Check status, balance, stepper | G21: 1. Status = 'Expired' 2. ETH refunded to user balance (only TX costs taken) 3. refund TX link shown under 3rd stepper step 4. stepper shown in green | H21: Not Run | I21: Contrast with 'Failed' where ETH not refunded. Note known bug: https://github.com/cowprotocol/cowswap/issues/4153
A22: MO-18 | B22: TX deadline: default value and limits (regular flow) | C22: High | D22: Functional | E22: EOA wallet connected; swap settings open | F22: 1. Open Settings 2. Check TX deadline default value 3. Try setting below minimum (< 2 min) 4. Try setting above maximum for EOA (> 180 min) 5. Reconnect with SC wallet and verify max changes to 720 min | G22: 1. Default = 30 min 2. min = 2 min (regular flow) 3. max EOA = 180 min 4. max SC wallet = 720 min 5. values outside range rejected or clamped | H22: Not Run | I22: Per spec. ETH-flow has different limits: min 10 min, max EOA 180 min, max SC 720 min
A23: MO-19 | B23: TX deadline: ETH-flow specific limits | C23: Medium | D23: Functional | E23: ETH-flow active (ETH sell token, EOA wallet); settings open | F23: 1. Open Settings with ETH-flow active 2. Check deadline default = 30 min 3. Try setting below 10 min 4. Try setting above 180 min (EOA) | G23: 1. ETH-flow min = 10 min (not 2 min) 2. deadline field labeled as 'modified' 3. values outside range rejected | H23: Not Run | I23: Per spec: ETH-flow min = 10 min vs regular flow min = 2 min
A24: MO-20 | B24: TX deadline: order expires after set deadline | C24: Medium | D24: Functional | E24: Order placed with short deadline (e.g. 2 min) | F24: 1. Set TX deadline to minimum (2 min) 2. Place order 3. Do not fill — wait for deadline to pass 4. Check order status | G24: Order status changes to 'Expired' after deadline; | H24: Not Run | I24: ~1 minute after real expiration
A25: MO-21 | B25: TX deadline: inactive tab quote expiry message | C25: Low | D25: Functional | E25: Quote loaded; tab left inactive for > 2 minutes | F25: 1. Load a swap quote 2. Leave the tab inactive for > 2 minutes 3. Return to tab | G25: 1. 'Quote expired. Refreshing…' message shown 2. refreshes within 10 seconds 3. if stuck > 10 sec may indicate BE rate limiting | H25: Not Run
A26: MO-22 | B26: Slippage: dynamic mode defaults and range (regular flow) | C26: High | D26: Functional | E26: Regular flow (ERC-20); settings open | F26: 1. Open Settings → Slippage 2. Verify dynamic is selected by default 3. Check dynamic range: min 0.5%, max dynamically up to 50% 4. Observe slippage auto-adjusts based on network conditions | G26: 1. Dynamic slippage selected by default 2. min = 0.5% 3. max = 50% 4. adjusts automatically 5. info banner 'Slippage adjusted to X% to ensure quick execution' appears when dynamic value > 2% | H26: Not Run
A27: MO-23 | B27: Slippage: manual mode — warnings at thresholds | C27: High | D27: Functional | E27: Regular flow; settings in manual slippage mode | F27: 1. Switch to manual slippage 2. Enter 0% → verify behavior 3. Enter 50% → verify accepted as max 4. Try entering 51% → verify rejected | G27: 1. 0.0% threshold: 'With low slippage, your transaction may expire. ' warning 2. >1% threshold: 'With high slippage, you may not get the best price.' warning 3. max = 50% 4. if dynamic disabled, 0.5% applied as default 5. 'recommended' label appears near value when dynamic is off | H27: Not Run | I27: Per spec: regular flow manual slippage
A28: MO-24 | B28: Slippage: ETH-flow defaults and limits | C28: Medium | D28: Functional | E28: ETH-flow active; settings open | F28: 1. Open Settings with ETH selected 4. Try setting below chain minimum 5. Try setting above 50% | G28: Min 0,5%, max 50% | H28: Not Run
A29: MO-25 | B29: Custom recipient: send swap output to different address | C29: High | D29: Functional | E29: Wallet connected; custom recipient field enabled in settings | F29: 1. Open Settings → enable Custom recipient 2. Enter a valid Ethereum address different from connected wallet 3. Place a swap order 4. On Confirm modal: verify warning about custom recipient is shown above Confirm button 5. Confirm and sign | G29: 1. Buy tokens received at the custom recipient address, not the connected wallet 2. warning displayed on confirm modal 3. order placed successfully | H29: Not Run
A30: MO-26 | B30: Custom recipient: field validation — invalid address | C30: High | D30: Negative | E30: Custom recipient field visible | F30: 1. Enter a non-address string (e.g. 'abc123') 2. Enter a partial address 3. Enter an address with wrong checksum 4. Observe field state | G30: 1. Recipient field value highlighted in red/error 2. 'Enter a valid recipient' error message displayed 3. Swap button disabled while invalid | H30: Not Run | I30: Per spec: 'The recipient field's value is highlighted; Enter a valid recipient is displayed'
A31: MO-27 | B31: Custom recipient: cross-chain prefix warning | C31: Medium | D31: Functional | E31: Connected to Ethereum Mainnet; custom recipient field open | F31: 1. Enter a recipient address with a different chain prefix (e.g. 'base:0x...' while connected to Ethereum) 2. Observe warning near the recipient field | G31: 1. Additional warning displayed near recipient field: recipient prefix differs from connected chain 2. does not block swap but warns user | H31: Not Run | I31: Per spec: 'E.g. you are connected to Ethereum, but insert a recipient address like base:address'
A32: MO-28 | B32: Custom recipient: ENS name resolution | C32: Low | D32: Functional | E32: Connected to Ethereum Mainnet (ENS supported); custom recipient enabled | F32: 1. Enter a valid ENS name (e.g. 'vitalik.eth') in recipient field 2. Observe resolution | G32: 1. ENS name resolved to 0x address 2. resolved address shown 3. no error state only on Ethreum and sepolia | H32: Not Run
A33: MO-29 | B33: Insufficient balance: error on swap form and unfillable label in Account modal | C33: High | D33: Negative | E33: Wallet connected with known token balances | F33: 1. Select a sell token 2. Enter amount greater than wallet balance 3. Observe UI | G33: 1. 'Insufficient [Token] balance' error displayed on swap form 2. Swap button disabled 3. if an open order exists for the same token and balance drops below order amount, the order is labeled unfillable in the Account modal order list | H33: Not Run
A34: MO-30 | B34: Token not approved (non-permittable, no bundling): approval button shown, order unfillable in Account modal | C34: High | D34: Functional | E34: ERC-20 sell token with no existing approval; wallet does not support bundling | F34: 1. Select an ERC-20 sell token with zero approval 2. Enter swap amount 3. Observe action button state | G34: 1. 'Allow CoW Swap to use your token' button shown on swap form 2. Swap button disabled until approved 3. any open order for this token shown as unfillable in Account modal due to insufficient allowance 4. for buy orders approval amount = Receive (incl. costs) + slippage | H34: Not Run | I34: Per spec
A35: MO-31 | B35: Token not approved — bundling supported: Approve+Swap button shown | C35: High | D35: Functional | E35: ERC-20 sell token with no approval; wallet supports bundling (e.g. Safe ) | F35: 1. Select unapproved ERC-20 token 2. Observe UI — 'Token bundling' banner should appear 3. Verify 'Approve + Swap' button shown | G35: 1. 'Approve + Swap' button displayed 2. token bundling banner shown above action button 3. both approval and swap sent to wallet in one go 4. open orders for this token shown as unfillable in Account modal until approval completes | H35: Not Run
A36: MO-32 | B36: Fee ≥ 30% of sell amount: red banner with 'Swap anyways' checkbox | C36: High | D36: Negative | E36: Trade with very small sell amount relative to network costs | F36: 1. Enter a very small sell amount so network fees ≥ 30% of sell value 2. Observe banner and button state | G36: 1. Red banner displayed 2. 'Swap anyways' checkbox shown unchecked 3. Swap button disabled until checkbox checked 4. red read-only banner also shown on Confirm modal | H36: Not Run | I36: Per spec: fee thresholds 30%=red, 20%=orange, 10%=yellow
A37: MO-33 | B37: Fee ≥ 20% orange banner, fee ≥ 10% yellow banner | C37: Medium | D37: Negative | E37: Trade amounts triggering fee thresholds | F37: 1. Enter amount where fee is 20–29% of sell value → observe orange banner 2. Enter amount where fee is 10–19% → observe yellow banner 3. In both cases verify 'Swap anyways' checkbox and button behavior | G37: 1. Orange banner at ≥20% 2. yellow banner at ≥10% 3. each requires user to check 'Swap anyways' box to enable Swap button 4. corresponding read-only banner shown on Confirm modal | H37: Not Run | I37: Per spec
A38: MO-34 | B38: Sell amount too small to cover min fee: error shown | C38: Medium | D38: Negative | E38: Very small sell amount entered | F38: 1. Enter a tiny sell amount (e.g. 0.0001 USDC) 2. Observe error | G38: 1. Error message displayed: sell amount not enough to cover minimum fee 2. Network costs (est.) field shown above the error with min trade amount | H38: Not Run | I38: Per spec: 'Error is displayed when sell amount is not enough to cover a min fee'
A39: MO-35 | B39: TWAP suggestion banner for large high-impact orders | C39: Medium | D39: Functional | E39: User has balance; large order (>$50k Mainnet / >$500 other chains); price impact > 1% | F39: 1. On Mainnet: enter sell amount > $50,000 USD equivalent 2. Ensure price impact > 1% 3. Observe banner | G39: 1. 'Minimize price impact with TWAP' banner displayed 2. thresholds: Mainnet $50k, Gnosis/Arbitrum/Base $500, Sepolia $100 | H39: Not Run | I39: Per spec thresholds
A40: MO-36 | B40: Error: no liquidity / token not supported | C40: Medium | D40: Negative | E40: Token pair with no liquidity or unsupported token selected | F40: 1. Select an obscure or unsupported token as sell or buy 2. Enter any amount | G40: 1. 'Insufficient liquidity for this trade' error message displayed 2. Swap button disabled | H40: Not Run | I40: Same message for both 'token not supported' and 'no liquidity for pair' cases
A41: MO-37 | B41: Error: price impact ≥ 5% — confirm price modal | C41: High | D41: Functional | E41: Trade with price impact ≥ 5% but < 10% | F41: 1. Set up trade with ≥5% price impact 2. Click 'Confirm Swap' 3. Observe additional confirmation modal | G41: 1. Secondary 'Confirm price' modal appears after clicking Confirm Swap 2. wallet signing request only sent after user confirms this modal | H41: Not Run | I41: Per spec
...

Sheet LimitOrders
A1: A4:F50
A2: B5
A3: B5:F15
A4: ID | B4: Test Name | C4: Priority | D4: Type | E4: Preconditions | F4: Test Steps | G4: Expected Result | H4: Status | I4: Notes / Defect ID
A5: LO-01 | B5: Place buy limit order | C5: High | D5: Functional | E5: Wallet connected; sufficient sell token balance | F5: 1. Click 'Limit' tab 2. Set sell token, buy token 3. Enter an exact amount into the Buy token field 4. set a limit price 5. Click 'Place limit order' 6. Sign in wallet | G5: 1. Limit order created 2. visible in open orders panel. Order type ia s Buy limit order (visible on the order receipt and on Explorer) | H5: Not Run
A6: LO-02 | B6: Place sell limit order | C6: High | D6: Functional | E6: Wallet has ERC-20 balance | F6: 1. Click 'Limit' tab 2. Set sell token, buy token 3. Enter an exact amount into the Sell token field 4. set a limit price 5. Click 'Place limit order' 6. Sign in wallet" | G6: 1. Sell limit order placed 2. shown in orders table. Order type is a Sell limit order (visible on the order receipt and on Explorer) | H6: Not Run
A7: LO-03 | B7: Partially fillable order execution | C7: High | D7: Functional | E7: Partial fill enabled (default) | F7: 1. Place a limit order with amount >balance, set a price below a market one 2. Check the order type in the order receipt 3. Check the order execution | G7: The order has 'partially filable' in its type. Same info if dsiplayed on Explorer When an order is filled partially, the percentage is adjusted on the limit orders table. Order is still displayed in the Open tab unless it is Expires or cancelled | H7: Not Run
A8: LO-04 | B8: Fill-or-kill order toggle | C8: Medium | D8: Functional | E8: Limit order panel open | F8: 1. Open settings 2. Disable 'Partially fillable' 3. Place order | G8: The order has 'Fill or kill ' in its type. Same info if dsiplayed on Explorer | H8: Not Run | I8: Partial approvals (setting allowance to exact trade amount) are NOT supported for limit orders — full (unlimited) on-chain approval or gasless permit required. EOA and MM Smart Account: permit available. SC wallets: on-chain only.
A9: LO-05 | B9: Cancel limit order | C9: High | D9: Functional | E9: Open limit order exists | F9: 1. Locate order in open orders 2. Open burger menu for the order 3. click on cancel and confirm the action 3. Sign cancellation | G9: It is a soft cancellation. the order goes into the Cancelling state and them changes its status to 'Cancelled.', and moved to the History tab from Open In case an order is already included into auction, the order stilll might be filled, so the status will be updated accordingly | H9: Not Run
A10: LO-06 | B10: Limit order expiry (custom duration) | C10: Medium | D10: Functional | E10: Limit order panel open | F10: 1. Set order duration (e.g., 35 min) 2. Place order with a limit price that won't be filled 3. Wait for expiry | G10: 1. Order expires after set duration 2. removed from open orders automatically | H10: Not Run | I10: Min custom duration is 30 minutes
A11: LO-07 | B11: Surplus capture on limit order | C11: High | D11: Functional | E11: Market price better than limit price at fill time | F11: 1. Place limit order below market 2. Observe fill price | G11: 1. Fill price better than limit price 2. surplus forwarded to user | H11: Not Run
A12: LO-08 | B12: 'Executes at' traffic light indicator | C12: Medium | D12: UI | E12: Open limit order panel | F12: 1. View open orders 2. Check 'Executes at' column | G12: 1. Green/yellow/red indicator shown 2. hover tooltip explains distance from execution | H12: Not Run
A13: LO-09 | B13: Place limit order with 1-year expiry | C13: Low | D13: Functional | E13: Wallet connected | F13: 1. Set duration to max (1 year) 2. Place order | G13: Order accepted with 1-year validity | H13: Not Run
A14: LO-10 | B14: Price displayed in USD toggle | C14: Low | D14: UI | E14: Limit order panel open | F14: 1. Toggle limit price display between native token and USD | G14: Price updates correctly in both modes without calculation errors | H14: Not Run
A15: LO-11 | B15: Sell limit order: place with balance ≥ 1 gwei (minimum) | C15: High | D15: Functional | E15: Wallet has sell token balance ≥ 1 gwei; limit order tab active | F15: 1. Select sell token with exactly 1 gwei balance (or smallest practical amount) 2. Enter sell amount > balance 3. Set limit price 4. Place order | G15: Order is placed | H15: Not Run | I15: If a token balance is 0, order cannot be placed
A16: LO-12 | B16: Sell limit order: place multiple orders with same balance | C16: High | D16: Functional | E16: Wallet has ERC-20 sell token; sufficient balance for multiple orders | F16: 1. Place first limit sell order for 50% of balance at price X 2. Place3-4 more same orders | G16: All orders are placed | H16: Not Run | I16: Unlimited order placement: same balance can back multiple concurrent orders
A17: LO-13 | B17: Limit order: unfillable state — insufficient balance at execution time | C17: High | D17: Functional | E17: Active open limit order; sell token balance subsequently spent or reduced below order amount | F17: 1. Place a fill or kill limit sell order for 100 USDC 2. Transfer out or spend the USDC so balance drops below order amount 3. Observe order status / UI indicator | G17: 1. Order marked as 'unfillable' or shows warning indicator 2. not immediately cancelled (it can become fillable again if balance is restored) 3. clear visual indicator in open orders table | H17: Not Run | I17: Order remains open but solver skips it until balance is restored
A18: LO-14 | B18: Limit order: unfillable state — insufficient allowance | C18: High | D18: Functional | E18: Active limit order; token approval subsequently revoked (e.g. via revoke.cash) | F18: 1. Place a limit order for an ERC-20 2. Revoke the token approval for CoW Protocol 3. Observe order status in the open orders table | G18: 1. Order shown as unfillable due to insufficient allowance 2. warning displayed 3. order not cancelled automatically 4. re-approving token restores fillability | H18: Not Run | I18: Partial approvals (setting allowance to exact trade amount) are NOT supported for limit orders — full (unlimited) on-chain approval or gasless permit required. EOA and MM Smart Account: permit available. SC wallets: on-chain only.
A19: LO-15 | B19: Limit order: unfillable state resolves when balance restored | C19: Medium | D19: Functional | E19: Order in unfillable state due to low balance | F19: 1. Start with order in unfillable state (from LO-16) 2. Top up sell token balance to cover order amount 3. Observe order status update | G19: 1. Order returns to normal active state 2. unfillable indicator cleared 3. eligible for next batch execution when price is reached | H19: Not Run
A20: LO-16 | B20: Orders table: navigate between Open, History tabs | C20: High | D20: Functional | E20: Wallet with orders in multiple states (open, filled, cancelled, expired) | F20: 1. Place at least one open order and have at least one order in History (filled, cancelled, or expired) 2. Open the orders table 3. Click the OPEN tab 4. Click the ORDERS HISTORY tab 5. Verify each tab shows the correct subset of orders | G20: 1. OPEN tab displays only currently open (active) orders 2. ORDERS HISTORY tab displays filled, cancelled, and expired orders 3. Tab switching is instant; no full page reload 4. Active tab is visually highlighted 5. Order counts match the actual orders for the connected wallet on the current chain | H20: Not Run
A21: LO-17 | B21: Orders table: three-dot menu actions per order | C21: Medium | D21: Functional | E21: Active open order in orders table | F21: 1. Hover over an open order row 2. Click the three-dot (⋮) menu 3. Verify available actions (Cancel, View on Explorer, order receipt.) | G21: 1. Three-dot menu shows relevant actions for order state: 'order receipt,' 'Cancel' for open orders, 'View on Explorer' for any order 2. actions execute correctly when selected | H21: Not Run
A22: LO-18 | B22: Orders table: order row shows current execution price | C22: Medium | D22: UI | E22: Open limit order in orders table | F22: 1. View open limit order in table 2. Check 'Executes at' column 3. Compare with set limit price | G22: 1. Current execution price shown (not just limit price) 2. traffic light color reflects proximity to execution 3. hovering shows tooltip with how far price needs to move | H22: Not Run | I22: Per spec: traffic light system — green/yellow/red based on current network fees and market price
A23: LO-19 | B23: Orders table: invert price display per order | C23: Low | D23: UI | E23: Open limit order visible in table | F23: 1. Click on the 'Executes at' price field for a specific order 2. Observe price direction change | G23: 1. Price display inverts for that individual order (e.g. ETH/USDC ↔ USDC/ETH) 2. hover text also reflects the inverted direction 3. other orders unaffected | H23: Not Run | I23: Per spec: 'Clicking on that field will invert the price display for the individual order'
A24: LO-20 | B24: Cancel limit order: off-chain soft cancellation (EOA) | C24: High | D24: Functional | E24: EOA wallet; active limit order | F24: 1. Locate open limit order in orders table 2. Click the ⋮ menu → 'Cancel order' 3. Sign the off-chain cancellation message in wallet (if available) 4. Observe order status | G24: 1. Off-chain cancellation message signed 2. order status changes to 'Cancelling' then 'Cancelled' 3. no gas TX on-chain 4. immediate effect — solvers stop attempting to fill the order | H24: Not Run | I24: Off-chain cancellation is gas-free for EOA. SC wallets cannot do off-chain soft cancellation — they must use on-chain TX
A25: LO-21 | B25: Cancel limit order: on-chain cancellation (EOA) | C25: High | D25: Functional | E25: EOA wallet; active limit order | F25: 1. Locate open limit order 2. Click cancel 3. Select on-chain cancellation option 4. Confirm and pay gas in wallet | G25: 1. On-chain cancellation TX submitted 2. gas paid 3. order cancelled with on-chain guarantee 4. order moves to 'cancelling' state | H25: Not Run | I25: On-chain cancellation is final and cannot be front-run
A26: LO-22 | B26: Cancel limit order: SC wallet — on-chain TX required (no soft cancel) | C26: High | D26: Functional | E26: Safe or other SC wallet; active limit order | F26: 1. Open orders table with SC wallet connected 2. Click cancel on a limit order 3. Observe cancellation flow | G26: 1. Only on-chain TX option available for SC wallets 2. Safe TX created in queue 3. requires threshold signatures 4. no off-chain soft cancellation available for SC wallets | H26: Not Run | I26: SC wallets cannot sign off-chain cancellation messages — on-chain is the only path
A27: LO-23 | B27: Cancel all orders: EOA wallet — bulk cancel via UI | C27: High | D27: Functional | E27: EOA wallet; 3+ active limit orders open | F27: 1. Navigate to the open orders table 2. Look for 'Cancel all' or bulk cancel option 3. Click Cancel all 4. Sign the cancellation (off-chain for all orders at once) | G27: 1. 'Cancel all' option available for EOA wallets 2. all open limit orders cancelled in a single off-chain signing action 3. no per-order gas 4. all orders status → Cancelled (if not filled: the cancellation is a soft one) | H27: Not Run | I27: Cancel all is EOA-only feature using off-chain signatures. SC wallets must cancel each order individually via on-chain TX
A28: LO-24 | B28: Cancel all orders: SC wallet — no bulk cancel available | C28: Medium | D28: Functional | E28: Safe or SC wallet; multiple active limit orders | F28: 1. Open orders table with SC wallet connected 2. Check whether 'Cancel all' option is present | G28: 1. 'Cancel all' option NOT available for SC wallets 2. each order must be cancelled individually via separate on-chain TXs 3. each cancellation requires threshold signatures in Safe | H28: Not Run
A29: LO-25 | B29: Recreate limit order from expired or cancelled order | C29: High | D29: Functional | E29: At least one felled, expired or cancelled limit order in history | F29: 1. Navigate to order history (filled, Cancelled or Expired tab) 2. Locate a limit order 3. Click 'Recreate order' in the menu or on order receipt 4. Verify form is pre-filled with original order parameters 5. Adjust if needed and place the order | G29: 1. Recreate option available on filled/expired/cancelled orders 2. clicking pre-fills the Limit order form with original: sell token, buy token, limit price, order type (sell/buy), fill mode 3. user can adjust before placing 4. new order placed as fresh order | H29: Not Run | I29: Recreate is a UX shortcut — should not copy the expired order ID, only its parameters
A30: LO-26 | B30: Limit order: gasless partial permit makes order unfillable — unfillable label shown | C30: High | D30: Functional | E30: EOA or MM Smart Account; open limit order for token X placed with gasless permit; a subsequent gasless partial permit for smaller amount signed for same token | F30: 1. Place limit order for 500 USDC (sign gasless permit for 500 USDC) 2. Place a market swap for 50 USDC with gasless permit for 50 USDC only 3. Return to Limit orders tab / orders table 4. Observe limit order status | G30: 1. Limit order labeled unfillable 2. unfillable indicator visible in open orders table 3. order not cancelled 4. tooltip or inline message indicates cause (insufficient allowance) 5. order stays unfillable until allowance is restored via on-chain approval | H30: Not Run | I30: Cross-reference MO-71. Both swap and limit orders are affected by partial permit side-effects.
